Workbook

Sheet FORECAST
E1: Ultima actualización | F1: 46122
A3: Salones | B3: Desde | C3: Hasta | D3: Estado | E3: Organizacion | F3: Descripción | G3: Room Rental | H3: N° de Asistentes
A4: LAS SIERRAS | B4: 46018.375 | C4: 46021.75 | D4: Garantizado | E4: Pretemporada | F4: Club Atlético Belgrano | H4: 40
A5: La Pampa ,LAS SIERRAS | B5: 46022.375 | C5: 46023.75 | D5: Garantizado | F5: Quinto Centenario Hotel | H5: 80
A6: La Pampa ,LAS SIERRAS | B6: 46022.375 | C6: 46023.75 | D6: Garantizado | F6: Quinto Centenario Hotel | H6: 80
A7: SALA A | B7: 46018 | C7: 46018 | D7: Garantizado | F7: INTENSITY SHOES S.R.L. | H7: 25
A8: LAS SIERRAS | B8: 46018 | C8: 46021 | D8: Garantizado | E8: Pretemporada | F8: Club Atlético Belgrano | H8: 40
A9: LUGONES A ,LUGONES B ,LUGONES C | B9: 46019 | C9: 46020 | D9: Garantizado | E9: MEETING DE LA EMPRESA | F9: Royal Prestige | H9: 750
A10: La Pampa ,LAS SIERRAS | B10: 46022 | C10: 46023 | D10: Garantizado | F10: Quinto Centenario Hotel | H10: 80
A11: YACANTO A y B ,YACANTO C | B11: 46025 | C11: 46028 | D11: Garantizado | E11: Pretemporada | F11: Club Atlético Belgrano | H11: 40
A12: LAS SIERRAS | B12: 46029 | C12: 46032 | D12: Garantizado | E12: Pretemporada | F12: Club Atlético Belgrano | H12: 40
A13: URITORCO A ,URITORCO B | B13: 46030 | C13: 46030 | D13: Garantizado | E13: Quinceañeras | F13: MAGIC DREAMS S.R.L | H13: 20
A14: Piscina | B14: 46031 | C14: 46031 | D14: Garantizado | E14: SUNSET FASHION & ART | F14: Nestor Moio | H14: 150
A15: SALA A | B15: 46037 | C15: 46037 | D15: Garantizado | F15: Joint Group SA | H15: 20
A16: SALA A | B16: 46042 | C16: 46043 | D16: Garantizado | F16: Puerta 7 SA | H16: 10
A17: CHAMPAQUI A | B17: 46044 | C17: 46044 | D17: Garantizado | E17: BELGRANO- Conferencia presentación refuerzos | F17: Club Atlético Belgrano | H17: 40
A18: Piscina ,LOBBY BAR | B18: 46045 | C18: 46045 | D18: Garantizado | E18: Sunset Fashion & Art | F18: Nestor Moio | H18: 100
A19: CHAMPAQUI A | B19: 46048 | C19: 46049 | D19: Garantizado | E19: Conferencia de prensa del Club Atlético Belgrano | F19: Club Atlético Belgrano | H19: 60
A20: YACANTO A y B ,YACANTO C | B20: 46050 | C20: 46051 | D20: Garantizado | E20: Belgrano Vs Tigre | F20: Club Atlético Belgrano | H20: 30
A21: SALA A | B21: 46053 | C21: 46053 | D21: Garantizado | E21: Taller de creación de perfumes PLANEANDO | F21: Planeando | H21: 10
A22: SALA D | B22: 46056 | C22: 46058 | D22: Garantizado | E22: Reunión _x000D_ Solicitada por MS | F22: Franco Emora
A23: La Pampa | B23: 46057 | C23: 46057 | D23: Presupuesto | E23: Festejo de cumpleaños asociados Diciembre 2025 | F23: Quinto Centenario Hotel | H23: 6
A24: SALA B | B24: 46058 | C24: 46058 | D24: Tentativo | E24: Entrevistas | F24: CAMARA DE COMERCIO DE LOS ESTADOS UNIDOS DE AMERIC | H24: 3
A25: YACANTO A y B ,YACANTO C | B25: 46059 | C25: 46060 | D25: Garantizado | E25: Belgrano vs Banfield | F25: Club Atlético Belgrano | H25: 30
A26: La Pampa | B26: 46064 | C26: 46064 | D26: Garantizado | E26: Festejo de cumpleaños asociados Enero 2026_x000D_ MERIENDA | F26: Quinto Centenario Hotel | H26: 10
A27: LAS SIERRAS | B27: 46065 | C27: 46065 | D27: Garantizado | E27: Cena | F27: Cámara de Industriales Metalúrgicos y Componentes | H27: 20
A28: CHAMPAQUI A ,CHAMPAQUI B | B28: 46065 | C28: 46065 | D28: Garantizado | E28: Conferencia | F28: Leonardo Villegas | G28: 563 | H28: 200
A29: YACANTO A y B ,YACANTO C ,CHAMPAQUI A ,CHAMPAQUI B | B29: 46066 | C29: 46067 | D29: Garantizado | F29: Gimnasia y Esgrima de Mendoza | H29: 42
A30: LAS SIERRAS | B30: 46067 | C30: 46067 | D30: Garantizado | E30: Dia de los enamorados | F30: Quinto Centenario Hotel | H30: 20
A31: Espejo de Agua | B31: 46067 | C31: 46067 | D31: Garantizado | E31: Día de los Enamorados (Espejo de agua) | F31: Quinto Centenario Hotel | H31: 20
A32: CHAMPAQUI A ,CHAMPAQUI B | B32: 46068 | C32: 46068 | D32: Garantizado | E32: Sesión Holisitica Diana Romano | F32: DWS S.A.S. | G32: 0 | H32: 180
A33: LAS SIERRAS | B33: 46072 | C33: 46072 | D33: Garantizado | E33: Cena Protocolar | F33: Skal Internacional | H33: 30
A34: YACANTO A y B ,YACANTO C ,URITORCO A ,URITORCO B | B34: 46076 | C34: 46077 | D34: Garantizado | E34: Belgrano vs Atletico Tucumán | F34: Club Atlético Belgrano | H34: 30
A35: SALA A | B35: 46079 | C35: 46080 | D35: Garantizado | F35: Julian Haynes | H35: 20
A36: URITORCO A ,URITORCO B | B36: 46079 | C36: 46079 | D36: Garantizado | F36: CAMARA ARGENTINA DE LA MICRO, PEQUEÑA Y MEDIANA EM | H36: 25
A37: YACANTO A y B ,YACANTO C | B37: 46080 | C37: 46084 | D37: Garantizado | E37: Comidas_x000D_ Cena 27/02_x000D_ Cena 28/02_x000D_ Cena 02/03_x000D_ Almuerzo 03/03 | F37: Colombia Basket | H37: 33
A38: CHAMPAQUI A ,CHAMPAQUI B ,YACANTO A y B ,YACANTO C ,SUQUIA A ,SUQUIA B ,URITORCO A ,URITORCO B | B38: 46080 | C38: 46081 | D38: Garantizado | F38: Club Atlético San Lorenzo de Almagro | H38: 47
A39: YACANTO A y B ,YACANTO C | B39: 46080 | C39: 46080 | D39: Garantizado | E39: Presentación +Cocktail | F39: Weldon Agency | G39: 400 | H39: 100
A40: LAS SIERRAS | B40: 46084 | C40: 46085 | D40: Garantizado | F40: TRANSPORTADORA DE GAS DEL NORTE S A | G40: 105 | H40: 15
A41: SALA A | B41: 46085 | C41: 46085 | D41: Garantizado | F41: NOVARTIS ARGENTINA S A | H41: 15
...

Sheet PLANNING 2026
O2: Referencias
P3: CONFIRMADO
P4: TENTATIVO
P5: PRESUPUESTO
P6: Fines de semana
P7: Feriados
P8: Mundial
C11: JU | D11: VI | E11: SA | F11: DO | G11: LU | H11: MA | I11: MI | J11: JU | K11: VI | L11: SA | M11: DO | N11: LU | O11: MA | P11: MI | Q11: JU | R11: VI | S11: SÁ. | T11: DO. | U11: LU. | V11: MA. | W11: MI. | X11: JU. | Y11: VI. | Z11: SÁ. | AA11: DO. | AB11: LU. | AC11: MA. | AD11: MI. | AE11: JU. | AF11: VI. | AG11: SÁ.
C12: 46023 | D12: 46024 | E12: 46025 | F12: 46026 | G12: 46027 | H12: 46028 | I12: 46029 | J12: 46030 | K12: 46031 | L12: 46032 | M12: 46033 | N12: 46034 | O12: 46035 | P12: 46036 | Q12: 46037 | R12: 46038 | S12: 46039 | T12: 46040 | U12: 46041 | V12: 46042 | W12: 46043 | X12: 46044 | Y12: 46045 | Z12: 46046 | AA12: 46047 | AB12: 46048 | AC12: 46049 | AD12: 46050 | AE12: 46051 | AF12: 46052 | AG12: 46053 | AJ12: Ocupación
A13: ENERO | B13: LUGONES | C13: {=IFERROR(INDEX(FORECAST!$D$3:$D$475, MATCH(1, INDEX((ISNUMBER(SEARCH($B13, FORECAST!$A$3:$A$475))) * (INT(FORECAST!$B$3:$B$475) <= C$12) * (INT(FORECAST!$C$3:$C$475) >= C$12), 0), 0)), "")} | D13: {=IFERROR(INDEX(FORECAST!$D$3:$D$475, MATCH(1, INDEX((ISNUMBER(SEARCH($B13, FORECAST!$A$3:$A$475))) * (INT(FORECAST!$B$3:$B$475) <= D$12) * (INT(FORECAST!$C$3:$C$475) >= D$12), 0), 0)), "")} | E13: {=IFERROR(INDEX(FORECAST!$D$3:$D$475, MATCH(1, INDEX((ISNUMBER(SEARCH($B13, FORECAST!$A$3:$A$475))) * (INT(FORECAST!$B$3:$B$475) <= E$12) * (INT(FORECAST!$C$3:$C$475) >= E$12), 0), 0)), "")} | F13: {=IFERROR(INDEX(FORECAST!$D$3:$D$475, MATCH(1, INDEX((ISNUMBER(SEARCH($B13, FORECAST!$A$3:$A$475))) * (INT(FORECAST!$B$3:$B$475) <= F$12) * (INT(FORECAST!$C$3:$C$475) >= F$12), 0), 0)), "")} | G13: {=IFERROR(INDEX(FORECAST!$D$3:$D$475, MATCH(1, INDEX((ISNUMBER(SEARCH($B13, FORECAST!$A$3:$A$475))) * (INT(FORECAST!$B$3:$B$475) <= G$12) * (INT(FORECAST!$C$3:$C$475) >= G$12), 0), 0)), "")} | H13: {=IFERROR(INDEX(FORECAST!$D$3:$D$475, MATCH(1, INDEX((ISNUMBER(SEARCH($B13, FORECAST!$A$3:$A$475))) * (INT(FORECAST!$B$3:$B$475) <= H$12) * (INT(FORECAST!$C$3:$C$475) >= H$12), 0), 0)), "")} | I13: {=IFERROR(INDEX(FORECAST!$D$3:$D$475, MATCH(1, INDEX((ISNUMBER(SEARCH($B13, FORECAST!$A$3:$A$475))) * (INT(FORECAST!$B$3:$B$475) <= I$12) * (INT(FORECAST!$C$3:$C$475) >= I$12), 0), 0)), "")} | J13: {=IFERROR(INDEX(FORECAST!$D$3:$D$475, MATCH(1, INDEX((ISNUMBER(SEARCH($B13, FORECAST!$A$3:$A$475))) * (INT(FORECAST!$B$3:$B$475) <= J$12) * (INT(FORECAST!$C$3:$C$475) >= J$12), 0), 0)), "")} | ... AG13: {=IFERROR(INDEX(FORECAST!$D$3:$D$475, MATCH(1, INDEX((ISNUMBER(SEARCH($B13, FORECAST!$A$3:$A$475))) * (INT(FORECAST!$B$3:$B$475) <= AG$12) * (INT(FORECAST!$C$3:$C$475) >= AG$12), 0), 0)), "")} | AJ13: =COUNTIF(C13:AG13,"Garantizado")/31 -> 0
B14: CHAMPAQUI | C14: {=IFERROR(INDEX(FORECAST!$D$3:$D$475, MATCH(1, INDEX((ISNUMBER(SEARCH($B14, FORECAST!$A$3:$A$475))) * (INT(FORECAST!$B$3:$B$475) <= C$12) * (INT(FORECAST!$C$3:$C$475) >= C$12), 0), 0)), "")} | D14: {=IFERROR(INDEX(FORECAST!$D$3:$D$475, MATCH(1, INDEX((ISNUMBER(SEARCH($B14, FORECAST!$A$3:$A$475))) * (INT(FORECAST!$B$3:$B$475) <= D$12) * (INT(FORECAST!$C$3:$C$475) >= D$12), 0), 0)), "")} | E14: {=IFERROR(INDEX(FORECAST!$D$3:$D$475, MATCH(1, INDEX((ISNUMBER(SEARCH($B14, FORECAST!$A$3:$A$475))) * (INT(FORECAST!$B$3:$B$475) <= E$12) * (INT(FORECAST!$C$3:$C$475) >= E$12), 0), 0)), "")} | F14: {=IFERROR(INDEX(FORECAST!$D$3:$D$475, MATCH(1, INDEX((ISNUMBER(SEARCH($B14, FORECAST!$A$3:$A$475))) * (INT(FORECAST!$B$3:$B$475) <= F$12) * (INT(FORECAST!$C$3:$C$475) >= F$12), 0), 0)), "")} | G14: {=IFERROR(INDEX(FORECAST!$D$3:$D$475, MATCH(1, INDEX((ISNUMBER(SEARCH($B14, FORECAST!$A$3:$A$475))) * (INT(FORECAST!$B$3:$B$475) <= G$12) * (INT(FORECAST!$C$3:$C$475) >= G$12), 0), 0)), "")} | H14: {=IFERROR(INDEX(FORECAST!$D$3:$D$475, MATCH(1, INDEX((ISNUMBER(SEARCH($B14, FORECAST!$A$3:$A$475))) * (INT(FORECAST!$B$3:$B$475) <= H$12) * (INT(FORECAST!$C$3:$C$475) >= H$12), 0), 0)), "")} | I14: {=IFERROR(INDEX(FORECAST!$D$3:$D$475, MATCH(1, INDEX((ISNUMBER(SEARCH($B14, FORECAST!$A$3:$A$475))) * (INT(FORECAST!$B$3:$B$475) <= I$12) * (INT(FORECAST!$C$3:$C$475) >= I$12), 0), 0)), "")} | J14: {=IFERROR(INDEX(FORECAST!$D$3:$D$475, MATCH(1, INDEX((ISNUMBER(SEARCH($B14, FORECAST!$A$3:$A$475))) * (INT(FORECAST!$B$3:$B$475) <= J$12) * (INT(FORECAST!$C$3:$C$475) >= J$12), 0), 0)), "")} | ... AG14: {=IFERROR(INDEX(FORECAST!$D$3:$D$475, MATCH(1, INDEX((ISNUMBER(SEARCH($B14, FORECAST!$A$3:$A$475))) * (INT(FORECAST!$B$3:$B$475) <= AG$12) * (INT(FORECAST!$C$3:$C$475) >= AG$12), 0), 0)), "")} | AJ14: =COUNTIF(C14:AG14,"Garantizado")/31 -> 0.096774194 | AL14: Ocupación Mensual Total
B15: TERRAZA | C15: {=IFERROR(INDEX(FORECAST!$D$3:$D$475, MATCH(1, INDEX((ISNUMBER(SEARCH($B15, FORECAST!$A$3:$A$475))) * (INT(FORECAST!$B$3:$B$475) <= C$12) * (INT(FORECAST!$C$3:$C$475) >= C$12), 0), 0)), "")} | D15: {=IFERROR(INDEX(FORECAST!$D$3:$D$475, MATCH(1, INDEX((ISNUMBER(SEARCH($B15, FORECAST!$A$3:$A$475))) * (INT(FORECAST!$B$3:$B$475) <= D$12) * (INT(FORECAST!$C$3:$C$475) >= D$12), 0), 0)), "")} | E15: {=IFERROR(INDEX(FORECAST!$D$3:$D$475, MATCH(1, INDEX((ISNUMBER(SEARCH($B15, FORECAST!$A$3:$A$475))) * (INT(FORECAST!$B$3:$B$475) <= E$12) * (INT(FORECAST!$C$3:$C$475) >= E$12), 0), 0)), "")} | F15: {=IFERROR(INDEX(FORECAST!$D$3:$D$475, MATCH(1, INDEX((ISNUMBER(SEARCH($B15, FORECAST!$A$3:$A$475))) * (INT(FORECAST!$B$3:$B$475) <= F$12) * (INT(FORECAST!$C$3:$C$475) >= F$12), 0), 0)), "")} | G15: {=IFERROR(INDEX(FORECAST!$D$3:$D$475, MATCH(1, INDEX((ISNUMBER(SEARCH($B15, FORECAST!$A$3:$A$475))) * (INT(FORECAST!$B$3:$B$475) <= G$12) * (INT(FORECAST!$C$3:$C$475) >= G$12), 0), 0)), "")} | H15: {=IFERROR(INDEX(FORECAST!$D$3:$D$475, MATCH(1, INDEX((ISNUMBER(SEARCH($B15, FORECAST!$A$3:$A$475))) * (INT(FORECAST!$B$3:$B$475) <= H$12) * (INT(FORECAST!$C$3:$C$475) >= H$12), 0), 0)), "")} | I15: {=IFERROR(INDEX(FORECAST!$D$3:$D$475, MATCH(1, INDEX((ISNUMBER(SEARCH($B15, FORECAST!$A$3:$A$475))) * (INT(FORECAST!$B$3:$B$475) <= I$12) * (INT(FORECAST!$C$3:$C$475) >= I$12), 0), 0)), "")} | J15: {=IFERROR(INDEX(FORECAST!$D$3:$D$475, MATCH(1, INDEX((ISNUMBER(SEARCH($B15, FORECAST!$A$3:$A$475))) * (INT(FORECAST!$B$3:$B$475) <= J$12) * (INT(FORECAST!$C$3:$C$475) >= J$12), 0), 0)), "")} | ... AG15: {=IFERROR(INDEX(FORECAST!$D$3:$D$475, MATCH(1, INDEX((ISNUMBER(SEARCH($B15, FORECAST!$A$3:$A$475))) * (INT(FORECAST!$B$3:$B$475) <= AG$12) * (INT(FORECAST!$C$3:$C$475) >= AG$12), 0), 0)), "")} | AJ15: =COUNTIF(C15:AG15,"Garantizado")/31 -> 0 | AL15: =COUNTIF('PLANNING 2026'!C13:AG19,"Garantizado")/COUNTA('PLANNING 2026'!C13:AG19) -> 0.069124424
B16: URITORCO | C16: {=IFERROR(INDEX(FORECAST!$D$3:$D$475, MATCH(1, INDEX((ISNUMBER(SEARCH($B16, FORECAST!$A$3:$A$475))) * (INT(FORECAST!$B$3:$B$475) <= C$12) * (INT(FORECAST!$C$3:$C$475) >= C$12), 0), 0)), "")} | D16: {=IFERROR(INDEX(FORECAST!$D$3:$D$475, MATCH(1, INDEX((ISNUMBER(SEARCH($B16, FORECAST!$A$3:$A$475))) * (INT(FORECAST!$B$3:$B$475) <= D$12) * (INT(FORECAST!$C$3:$C$475) >= D$12), 0), 0)), "")} | E16: {=IFERROR(INDEX(FORECAST!$D$3:$D$475, MATCH(1, INDEX((ISNUMBER(SEARCH($B16, FORECAST!$A$3:$A$475))) * (INT(FORECAST!$B$3:$B$475) <= E$12) * (INT(FORECAST!$C$3:$C$475) >= E$12), 0), 0)), "")} | F16: {=IFERROR(INDEX(FORECAST!$D$3:$D$475, MATCH(1, INDEX((ISNUMBER(SEARCH($B16, FORECAST!$A$3:$A$475))) * (INT(FORECAST!$B$3:$B$475) <= F$12) * (INT(FORECAST!$C$3:$C$475) >= F$12), 0), 0)), "")} | G16: {=IFERROR(INDEX(FORECAST!$D$3:$D$475, MATCH(1, INDEX((ISNUMBER(SEARCH($B16, FORECAST!$A$3:$A$475))) * (INT(FORECAST!$B$3:$B$475) <= G$12) * (INT(FORECAST!$C$3:$C$475) >= G$12), 0), 0)), "")} | H16: {=IFERROR(INDEX(FORECAST!$D$3:$D$475, MATCH(1, INDEX((ISNUMBER(SEARCH($B16, FORECAST!$A$3:$A$475))) * (INT(FORECAST!$B$3:$B$475) <= H$12) * (INT(FORECAST!$C$3:$C$475) >= H$12), 0), 0)), "")} | I16: {=IFERROR(INDEX(FORECAST!$D$3:$D$475, MATCH(1, INDEX((ISNUMBER(SEARCH($B16, FORECAST!$A$3:$A$475))) * (INT(FORECAST!$B$3:$B$475) <= I$12) * (INT(FORECAST!$C$3:$C$475) >= I$12), 0), 0)), "")} | J16: {=IFERROR(INDEX(FORECAST!$D$3:$D$475, MATCH(1, INDEX((ISNUMBER(SEARCH($B16, FORECAST!$A$3:$A$475))) * (INT(FORECAST!$B$3:$B$475) <= J$12) * (INT(FORECAST!$C$3:$C$475) >= J$12), 0), 0)), "")} -> Garantizado | ... AG16: {=IFERROR(INDEX(FORECAST!$D$3:$D$475, MATCH(1, INDEX((ISNUMBER(SEARCH($B16, FORECAST!$A$3:$A$475))) * (INT(FORECAST!$B$3:$B$475) <= AG$12) * (INT(FORECAST!$C$3:$C$475) >= AG$12), 0), 0)), "")} | AJ16: =COUNTIF(C16:AG16,"Garantizado")/31 -> 0.032258065
B17: SUQUIA | C17: {=IFERROR(INDEX(FORECAST!$D$3:$D$475, MATCH(1, INDEX((ISNUMBER(SEARCH($B17, FORECAST!$A$3:$A$475))) * (INT(FORECAST!$B$3:$B$475) <= C$12) * (INT(FORECAST!$C$3:$C$475) >= C$12), 0), 0)), "")} | D17: {=IFERROR(INDEX(FORECAST!$D$3:$D$475, MATCH(1, INDEX((ISNUMBER(SEARCH($B17, FORECAST!$A$3:$A$475))) * (INT(FORECAST!$B$3:$B$475) <= D$12) * (INT(FORECAST!$C$3:$C$475) >= D$12), 0), 0)), "")} | E17: {=IFERROR(INDEX(FORECAST!$D$3:$D$475, MATCH(1, INDEX((ISNUMBER(SEARCH($B17, FORECAST!$A$3:$A$475))) * (INT(FORECAST!$B$3:$B$475) <= E$12) * (INT(FORECAST!$C$3:$C$475) >= E$12), 0), 0)), "")} | F17: {=IFERROR(INDEX(FORECAST!$D$3:$D$475, MATCH(1, INDEX((ISNUMBER(SEARCH($B17, FORECAST!$A$3:$A$475))) * (INT(FORECAST!$B$3:$B$475) <= F$12) * (INT(FORECAST!$C$3:$C$475) >= F$12), 0), 0)), "")} | G17: {=IFERROR(INDEX(FORECAST!$D$3:$D$475, MATCH(1, INDEX((ISNUMBER(SEARCH($B17, FORECAST!$A$3:$A$475))) * (INT(FORECAST!$B$3:$B$475) <= G$12) * (INT(FORECAST!$C$3:$C$475) >= G$12), 0), 0)), "")} | H17: {=IFERROR(INDEX(FORECAST!$D$3:$D$475, MATCH(1, INDEX((ISNUMBER(SEARCH($B17, FORECAST!$A$3:$A$475))) * (INT(FORECAST!$B$3:$B$475) <= H$12) * (INT(FORECAST!$C$3:$C$475) >= H$12), 0), 0)), "")} | I17: {=IFERROR(INDEX(FORECAST!$D$3:$D$475, MATCH(1, INDEX((ISNUMBER(SEARCH($B17, FORECAST!$A$3:$A$475))) * (INT(FORECAST!$B$3:$B$475) <= I$12) * (INT(FORECAST!$C$3:$C$475) >= I$12), 0), 0)), "")} | J17: {=IFERROR(INDEX(FORECAST!$D$3:$D$475, MATCH(1, INDEX((ISNUMBER(SEARCH($B17, FORECAST!$A$3:$A$475))) * (INT(FORECAST!$B$3:$B$475) <= J$12) * (INT(FORECAST!$C$3:$C$475) >= J$12), 0), 0)), "")} | ... AG17: {=IFERROR(INDEX(FORECAST!$D$3:$D$475, MATCH(1, INDEX((ISNUMBER(SEARCH($B17, FORECAST!$A$3:$A$475))) * (INT(FORECAST!$B$3:$B$475) <= AG$12) * (INT(FORECAST!$C$3:$C$475) >= AG$12), 0), 0)), "")} | AJ17: =COUNTIF(C17:AG17,"Garantizado")/31 -> 0
B18: YACANTO | C18: {=IFERROR(INDEX(FORECAST!$D$3:$D$475, MATCH(1, INDEX((ISNUMBER(SEARCH($B18, FORECAST!$A$3:$A$475))) * (INT(FORECAST!$B$3:$B$475) <= C$12) * (INT(FORECAST!$C$3:$C$475) >= C$12), 0), 0)), "")} | D18: {=IFERROR(INDEX(FORECAST!$D$3:$D$475, MATCH(1, INDEX((ISNUMBER(SEARCH($B18, FORECAST!$A$3:$A$475))) * (INT(FORECAST!$B$3:$B$475) <= D$12) * (INT(FORECAST!$C$3:$C$475) >= D$12), 0), 0)), "")} | E18: {=IFERROR(INDEX(FORECAST!$D$3:$D$475, MATCH(1, INDEX((ISNUMBER(SEARCH($B18, FORECAST!$A$3:$A$475))) * (INT(FORECAST!$B$3:$B$475) <= E$12) * (INT(FORECAST!$C$3:$C$475) >= E$12), 0), 0)), "")} -> Garantizado | F18: {=IFERROR(INDEX(FORECAST!$D$3:$D$475, MATCH(1, INDEX((ISNUMBER(SEARCH($B18, FORECAST!$A$3:$A$475))) * (INT(FORECAST!$B$3:$B$475) <= F$12) * (INT(FORECAST!$C$3:$C$475) >= F$12), 0), 0)), "")} -> Garantizado | G18: {=IFERROR(INDEX(FORECAST!$D$3:$D$475, MATCH(1, INDEX((ISNUMBER(SEARCH($B18, FORECAST!$A$3:$A$475))) * (INT(FORECAST!$B$3:$B$475) <= G$12) * (INT(FORECAST!$C$3:$C$475) >= G$12), 0), 0)), "")} -> Garantizado | H18: {=IFERROR(INDEX(FORECAST!$D$3:$D$475, MATCH(1, INDEX((ISNUMBER(SEARCH($B18, FORECAST!$A$3:$A$475))) * (INT(FORECAST!$B$3:$B$475) <= H$12) * (INT(FORECAST!$C$3:$C$475) >= H$12), 0), 0)), "")} -> Garantizado | I18: {=IFERROR(INDEX(FORECAST!$D$3:$D$475, MATCH(1, INDEX((ISNUMBER(SEARCH($B18, FORECAST!$A$3:$A$475))) * (INT(FORECAST!$B$3:$B$475) <= I$12) * (INT(FORECAST!$C$3:$C$475) >= I$12), 0), 0)), "")} | J18: {=IFERROR(INDEX(FORECAST!$D$3:$D$475, MATCH(1, INDEX((ISNUMBER(SEARCH($B18, FORECAST!$A$3:$A$475))) * (INT(FORECAST!$B$3:$B$475) <= J$12) * (INT(FORECAST!$C$3:$C$475) >= J$12), 0), 0)), "")} | ... AG18: {=IFERROR(INDEX(FORECAST!$D$3:$D$475, MATCH(1, INDEX((ISNUMBER(SEARCH($B18, FORECAST!$A$3:$A$475))) * (INT(FORECAST!$B$3:$B$475) <= AG$12) * (INT(FORECAST!$C$3:$C$475) >= AG$12), 0), 0)), "")} | AJ18: =COUNTIF(C18:AG18,"Garantizado")/31 -> 0.19354839
B19: LAS SIERRAS | C19: {=IFERROR(INDEX(FORECAST!$D$3:$D$475, MATCH(1, INDEX((ISNUMBER(SEARCH($B19, FORECAST!$A$3:$A$475))) * (INT(FORECAST!$B$3:$B$475) <= C$12) * (INT(FORECAST!$C$3:$C$475) >= C$12), 0), 0)), "")} -> Garantizado | D19: {=IFERROR(INDEX(FORECAST!$D$3:$D$475, MATCH(1, INDEX((ISNUMBER(SEARCH($B19, FORECAST!$A$3:$A$475))) * (INT(FORECAST!$B$3:$B$475) <= D$12) * (INT(FORECAST!$C$3:$C$475) >= D$12), 0), 0)), "")} | E19: {=IFERROR(INDEX(FORECAST!$D$3:$D$475, MATCH(1, INDEX((ISNUMBER(SEARCH($B19, FORECAST!$A$3:$A$475))) * (INT(FORECAST!$B$3:$B$475) <= E$12) * (INT(FORECAST!$C$3:$C$475) >= E$12), 0), 0)), "")} | F19: {=IFERROR(INDEX(FORECAST!$D$3:$D$475, MATCH(1, INDEX((ISNUMBER(SEARCH($B19, FORECAST!$A$3:$A$475))) * (INT(FORECAST!$B$3:$B$475) <= F$12) * (INT(FORECAST!$C$3:$C$475) >= F$12), 0), 0)), "")} | G19: {=IFERROR(INDEX(FORECAST!$D$3:$D$475, MATCH(1, INDEX((ISNUMBER(SEARCH($B19, FORECAST!$A$3:$A$475))) * (INT(FORECAST!$B$3:$B$475) <= G$12) * (INT(FORECAST!$C$3:$C$475) >= G$12), 0), 0)), "")} | H19: {=IFERROR(INDEX(FORECAST!$D$3:$D$475, MATCH(1, INDEX((ISNUMBER(SEARCH($B19, FORECAST!$A$3:$A$475))) * (INT(FORECAST!$B$3:$B$475) <= H$12) * (INT(FORECAST!$C$3:$C$475) >= H$12), 0), 0)), "")} | I19: {=IFERROR(INDEX(FORECAST!$D$3:$D$475, MATCH(1, INDEX((ISNUMBER(SEARCH($B19, FORECAST!$A$3:$A$475))) * (INT(FORECAST!$B$3:$B$475) <= I$12) * (INT(FORECAST!$C$3:$C$475) >= I$12), 0), 0)), "")} -> Garantizado | J19: {=IFERROR(INDEX(FORECAST!$D$3:$D$475, MATCH(1, INDEX((ISNUMBER(SEARCH($B19, FORECAST!$A$3:$A$475))) * (INT(FORECAST!$B$3:$B$475) <= J$12) * (INT(FORECAST!$C$3:$C$475) >= J$12), 0), 0)), "")} -> Garantizado | ... AG19: {=IFERROR(INDEX(FORECAST!$D$3:$D$475, MATCH(1, INDEX((ISNUMBER(SEARCH($B19, FORECAST!$A$3:$A$475))) * (INT(FORECAST!$B$3:$B$475) <= AG$12) * (INT(FORECAST!$C$3:$C$475) >= AG$12), 0), 0)), "")} | AJ19: =COUNTIF(C19:AG19,"Garantizado")/31 -> 0.16129032
B20: SAN JAVIER | C20: {=IFERROR(INDEX(FORECAST!$D$3:$D$475, MATCH(1, INDEX((ISNUMBER(SEARCH($B20, FORECAST!$A$3:$A$475))) * (INT(FORECAST!$B$3:$B$475) <= C$12) * (INT(FORECAST!$C$3:$C$475) >= C$12), 0), 0)), "")} | D20: {=IFERROR(INDEX(FORECAST!$D$3:$D$475, MATCH(1, INDEX((ISNUMBER(SEARCH($B20, FORECAST!$A$3:$A$475))) * (INT(FORECAST!$B$3:$B$475) <= D$12) * (INT(FORECAST!$C$3:$C$475) >= D$12), 0), 0)), "")} | E20: {=IFERROR(INDEX(FORECAST!$D$3:$D$475, MATCH(1, INDEX((ISNUMBER(SEARCH($B20, FORECAST!$A$3:$A$475))) * (INT(FORECAST!$B$3:$B$475) <= E$12) * (INT(FORECAST!$C$3:$C$475) >= E$12), 0), 0)), "")} | F20: {=IFERROR(INDEX(FORECAST!$D$3:$D$475, MATCH(1, INDEX((ISNUMBER(SEARCH($B20, FORECAST!$A$3:$A$475))) * (INT(FORECAST!$B$3:$B$475) <= F$12) * (INT(FORECAST!$C$3:$C$475) >= F$12), 0), 0)), "")} | G20: {=IFERROR(INDEX(FORECAST!$D$3:$D$475, MATCH(1, INDEX((ISNUMBER(SEARCH($B20, FORECAST!$A$3:$A$475))) * (INT(FORECAST!$B$3:$B$475) <= G$12) * (INT(FORECAST!$C$3:$C$475) >= G$12), 0), 0)), "")} | H20: {=IFERROR(INDEX(FORECAST!$D$3:$D$475, MATCH(1, INDEX((ISNUMBER(SEARCH($B20, FORECAST!$A$3:$A$475))) * (INT(FORECAST!$B$3:$B$475) <= H$12) * (INT(FORECAST!$C$3:$C$475) >= H$12), 0), 0)), "")} | I20: {=IFERROR(INDEX(FORECAST!$D$3:$D$475, MATCH(1, INDEX((ISNUMBER(SEARCH($B20, FORECAST!$A$3:$A$475))) * (INT(FORECAST!$B$3:$B$475) <= I$12) * (INT(FORECAST!$C$3:$C$475) >= I$12), 0), 0)), "")} | J20: {=IFERROR(INDEX(FORECAST!$D$3:$D$475, MATCH(1, INDEX((ISNUMBER(SEARCH($B20, FORECAST!$A$3:$A$475))) * (INT(FORECAST!$B$3:$B$475) <= J$12) * (INT(FORECAST!$C$3:$C$475) >= J$12), 0), 0)), "")} | ... AG20: {=IFERROR(INDEX(FORECAST!$D$3:$D$475, MATCH(1, INDEX((ISNUMBER(SEARCH($B20, FORECAST!$A$3:$A$475))) * (INT(FORECAST!$B$3:$B$475) <= AG$12) * (INT(FORECAST!$C$3:$C$475) >= AG$12), 0), 0)), "")} | AJ20: =COUNTIF(C20:AG20,"Garantizado")/31 -> 0
C22: DO | D22: LU | E22: MA | F22: MI | G22: JU | H22: VI | I22: SA | J22: DO | K22: LU | L22: MA | M22: MI | N22: JU | O22: VI | P22: SA | Q22: DO | R22: LU | S22: MA | T22: MI | U22: JU | V22: VI | W22: SÁ. | X22: DO. | Y22: LU. | Z22: MA. | AA22: MI. | AB22: JU. | AC22: VI. | AD22: SÁ.
C23: 46054 | D23: 46055 | E23: 46056 | F23: 46057 | G23: 46058 | H23: 46059 | I23: 46060 | J23: 46061 | K23: 46062 | L23: 46063 | M23: 46064 | N23: 46065 | O23: 46066 | P23: 46067 | Q23: 46068 | R23: 46069 | S23: 46070 | T23: 46071 | U23: 46072 | V23: 46073 | W23: 46074 | X23: 46075 | Y23: 46076 | Z23: 46077 | AA23: 46078 | AB23: 46079 | AC23: 46080 | AD23: 46081 | AJ23: Ocupación
A24: FEBRERO | B24: LUGONES | C24: {=IFERROR(INDEX(FORECAST!$D$3:$D$475, MATCH(1, INDEX((ISNUMBER(SEARCH($B24, FORECAST!$A$3:$A$475))) * (INT(FORECAST!$B$3:$B$475) <= C$23) * (INT(FORECAST!$C$3:$C$475) >= C$23), 0), 0)), "")} | D24: {=IFERROR(INDEX(FORECAST!$D$3:$D$475, MATCH(1, INDEX((ISNUMBER(SEARCH($B24, FORECAST!$A$3:$A$475))) * (INT(FORECAST!$B$3:$B$475) <= D$23) * (INT(FORECAST!$C$3:$C$475) >= D$23), 0), 0)), "")} | E24: {=IFERROR(INDEX(FORECAST!$D$3:$D$475, MATCH(1, INDEX((ISNUMBER(SEARCH($B24, FORECAST!$A$3:$A$475))) * (INT(FORECAST!$B$3:$B$475) <= E$23) * (INT(FORECAST!$C$3:$C$475) >= E$23), 0), 0)), "")} | F24: {=IFERROR(INDEX(FORECAST!$D$3:$D$475, MATCH(1, INDEX((ISNUMBER(SEARCH($B24, FORECAST!$A$3:$A$475))) * (INT(FORECAST!$B$3:$B$475) <= F$23) * (INT(FORECAST!$C$3:$C$475) >= F$23), 0), 0)), "")} | G24: {=IFERROR(INDEX(FORECAST!$D$3:$D$475, MATCH(1, INDEX((ISNUMBER(SEARCH($B24, FORECAST!$A$3:$A$475))) * (INT(FORECAST!$B$3:$B$475) <= G$23) * (INT(FORECAST!$C$3:$C$475) >= G$23), 0), 0)), "")} | H24: {=IFERROR(INDEX(FORECAST!$D$3:$D$475, MATCH(1, INDEX((ISNUMBER(SEARCH($B24, FORECAST!$A$3:$A$475))) * (INT(FORECAST!$B$3:$B$475) <= H$23) * (INT(FORECAST!$C$3:$C$475) >= H$23), 0), 0)), "")} | I24: {=IFERROR(INDEX(FORECAST!$D$3:$D$475, MATCH(1, INDEX((ISNUMBER(SEARCH($B24, FORECAST!$A$3:$A$475))) * (INT(FORECAST!$B$3:$B$475) <= I$23) * (INT(FORECAST!$C$3:$C$475) >= I$23), 0), 0)), "")} | J24: {=IFERROR(INDEX(FORECAST!$D$3:$D$475, MATCH(1, INDEX((ISNUMBER(SEARCH($B24, FORECAST!$A$3:$A$475))) * (INT(FORECAST!$B$3:$B$475) <= J$23) * (INT(FORECAST!$C$3:$C$475) >= J$23), 0), 0)), "")} | ... AD24: {=IFERROR(INDEX(FORECAST!$D$3:$D$475, MATCH(1, INDEX((ISNUMBER(SEARCH($B24, FORECAST!$A$3:$A$475))) * (INT(FORECAST!$B$3:$B$475) <= AD$23) * (INT(FORECAST!$C$3:$C$475) >= AD$23), 0), 0)), "")} | AJ24: =COUNTIF(C24:AD24,"Garantizado")/28 -> 0
B25: CHAMPAQUI | C25: {=IFERROR(INDEX(FORECAST!$D$3:$D$475, MATCH(1, INDEX((ISNUMBER(SEARCH($B25, FORECAST!$A$3:$A$475))) * (INT(FORECAST!$B$3:$B$475) <= C$23) * (INT(FORECAST!$C$3:$C$475) >= C$23), 0), 0)), "")} | D25: {=IFERROR(INDEX(FORECAST!$D$3:$D$475, MATCH(1, INDEX((ISNUMBER(SEARCH($B25, FORECAST!$A$3:$A$475))) * (INT(FORECAST!$B$3:$B$475) <= D$23) * (INT(FORECAST!$C$3:$C$475) >= D$23), 0), 0)), "")} | E25: {=IFERROR(INDEX(FORECAST!$D$3:$D$475, MATCH(1, INDEX((ISNUMBER(SEARCH($B25, FORECAST!$A$3:$A$475))) * (INT(FORECAST!$B$3:$B$475) <= E$23) * (INT(FORECAST!$C$3:$C$475) >= E$23), 0), 0)), "")} | F25: {=IFERROR(INDEX(FORECAST!$D$3:$D$475, MATCH(1, INDEX((ISNUMBER(SEARCH($B25, FORECAST!$A$3:$A$475))) * (INT(FORECAST!$B$3:$B$475) <= F$23) * (INT(FORECAST!$C$3:$C$475) >= F$23), 0), 0)), "")} | G25: {=IFERROR(INDEX(FORECAST!$D$3:$D$475, MATCH(1, INDEX((ISNUMBER(SEARCH($B25, FORECAST!$A$3:$A$475))) * (INT(FORECAST!$B$3:$B$475) <= G$23) * (INT(FORECAST!$C$3:$C$475) >= G$23), 0), 0)), "")} | H25: {=IFERROR(INDEX(FORECAST!$D$3:$D$475, MATCH(1, INDEX((ISNUMBER(SEARCH($B25, FORECAST!$A$3:$A$475))) * (INT(FORECAST!$B$3:$B$475) <= H$23) * (INT(FORECAST!$C$3:$C$475) >= H$23), 0), 0)), "")} | I25: {=IFERROR(INDEX(FORECAST!$D$3:$D$475, MATCH(1, INDEX((ISNUMBER(SEARCH($B25, FORECAST!$A$3:$A$475))) * (INT(FORECAST!$B$3:$B$475) <= I$23) * (INT(FORECAST!$C$3:$C$475) >= I$23), 0), 0)), "")} | J25: {=IFERROR(INDEX(FORECAST!$D$3:$D$475, MATCH(1, INDEX((ISNUMBER(SEARCH($B25, FORECAST!$A$3:$A$475))) * (INT(FORECAST!$B$3:$B$475) <= J$23) * (INT(FORECAST!$C$3:$C$475) >= J$23), 0), 0)), "")} | ... AD25: {=IFERROR(INDEX(FORECAST!$D$3:$D$475, MATCH(1, INDEX((ISNUMBER(SEARCH($B25, FORECAST!$A$3:$A$475))) * (INT(FORECAST!$B$3:$B$475) <= AD$23) * (INT(FORECAST!$C$3:$C$475) >= AD$23), 0), 0)), "")} -> Garantizado | AJ25: =COUNTIF(C25:AD25,"Garantizado")/28 -> 0.21428571
B26: TERRAZA | C26: {=IFERROR(INDEX(FORECAST!$D$3:$D$475, MATCH(1, INDEX((ISNUMBER(SEARCH($B26, FORECAST!$A$3:$A$475))) * (INT(FORECAST!$B$3:$B$475) <= C$23) * (INT(FORECAST!$C$3:$C$475) >= C$23), 0), 0)), "")} | D26: {=IFERROR(INDEX(FORECAST!$D$3:$D$475, MATCH(1, INDEX((ISNUMBER(SEARCH($B26, FORECAST!$A$3:$A$475))) * (INT(FORECAST!$B$3:$B$475) <= D$23) * (INT(FORECAST!$C$3:$C$475) >= D$23), 0), 0)), "")} | E26: {=IFERROR(INDEX(FORECAST!$D$3:$D$475, MATCH(1, INDEX((ISNUMBER(SEARCH($B26, FORECAST!$A$3:$A$475))) * (INT(FORECAST!$B$3:$B$475) <= E$23) * (INT(FORECAST!$C$3:$C$475) >= E$23), 0), 0)), "")} | F26: {=IFERROR(INDEX(FORECAST!$D$3:$D$475, MATCH(1, INDEX((ISNUMBER(SEARCH($B26, FORECAST!$A$3:$A$475))) * (INT(FORECAST!$B$3:$B$475) <= F$23) * (INT(FORECAST!$C$3:$C$475) >= F$23), 0), 0)), "")} | G26: {=IFERROR(INDEX(FORECAST!$D$3:$D$475, MATCH(1, INDEX((ISNUMBER(SEARCH($B26, FORECAST!$A$3:$A$475))) * (INT(FORECAST!$B$3:$B$475) <= G$23) * (INT(FORECAST!$C$3:$C$475) >= G$23), 0), 0)), "")} | H26: {=IFERROR(INDEX(FORECAST!$D$3:$D$475, MATCH(1, INDEX((ISNUMBER(SEARCH($B26, FORECAST!$A$3:$A$475))) * (INT(FORECAST!$B$3:$B$475) <= H$23) * (INT(FORECAST!$C$3:$C$475) >= H$23), 0), 0)), "")} | I26: {=IFERROR(INDEX(FORECAST!$D$3:$D$475, MATCH(1, INDEX((ISNUMBER(SEARCH($B26, FORECAST!$A$3:$A$475))) * (INT(FORECAST!$B$3:$B$475) <= I$23) * (INT(FORECAST!$C$3:$C$475) >= I$23), 0), 0)), "")} | J26: {=IFERROR(INDEX(FORECAST!$D$3:$D$475, MATCH(1, INDEX((ISNUMBER(SEARCH($B26, FORECAST!$A$3:$A$475))) * (INT(FORECAST!$B$3:$B$475) <= J$23) * (INT(FORECAST!$C$3:$C$475) >= J$23), 0), 0)), "")} | ... AD26: {=IFERROR(INDEX(FORECAST!$D$3:$D$475, MATCH(1, INDEX((ISNUMBER(SEARCH($B26, FORECAST!$A$3:$A$475))) * (INT(FORECAST!$B$3:$B$475) <= AD$23) * (INT(FORECAST!$C$3:$C$475) >= AD$23), 0), 0)), "")} | AJ26: =COUNTIF(C26:AD26,"Garantizado")/28 -> 0 | AL26: Ocupación Mensual Total
B27: URITORCO | C27: {=IFERROR(INDEX(FORECAST!$D$3:$D$475, MATCH(1, INDEX((ISNUMBER(SEARCH($B27, FORECAST!$A$3:$A$475))) * (INT(FORECAST!$B$3:$B$475) <= C$23) * (INT(FORECAST!$C$3:$C$475) >= C$23), 0), 0)), "")} | D27: {=IFERROR(INDEX(FORECAST!$D$3:$D$475, MATCH(1, INDEX((ISNUMBER(SEARCH($B27, FORECAST!$A$3:$A$475))) * (INT(FORECAST!$B$3:$B$475) <= D$23) * (INT(FORECAST!$C$3:$C$475) >= D$23), 0), 0)), "")} | E27: {=IFERROR(INDEX(FORECAST!$D$3:$D$475, MATCH(1, INDEX((ISNUMBER(SEARCH($B27, FORECAST!$A$3:$A$475))) * (INT(FORECAST!$B$3:$B$475) <= E$23) * (INT(FORECAST!$C$3:$C$475) >= E$23), 0), 0)), "")} | F27: {=IFERROR(INDEX(FORECAST!$D$3:$D$475, MATCH(1, INDEX((ISNUMBER(SEARCH($B27, FORECAST!$A$3:$A$475))) * (INT(FORECAST!$B$3:$B$475) <= F$23) * (INT(FORECAST!$C$3:$C$475) >= F$23), 0), 0)), "")} | G27: {=IFERROR(INDEX(FORECAST!$D$3:$D$475, MATCH(1, INDEX((ISNUMBER(SEARCH($B27, FORECAST!$A$3:$A$475))) * (INT(FORECAST!$B$3:$B$475) <= G$23) * (INT(FORECAST!$C$3:$C$475) >= G$23), 0), 0)), "")} | H27: {=IFERROR(INDEX(FORECAST!$D$3:$D$475, MATCH(1, INDEX((ISNUMBER(SEARCH($B27, FORECAST!$A$3:$A$475))) * (INT(FORECAST!$B$3:$B$475) <= H$23) * (INT(FORECAST!$C$3:$C$475) >= H$23), 0), 0)), "")} | I27: {=IFERROR(INDEX(FORECAST!$D$3:$D$475, MATCH(1, INDEX((ISNUMBER(SEARCH($B27, FORECAST!$A$3:$A$475))) * (INT(FORECAST!$B$3:$B$475) <= I$23) * (INT(FORECAST!$C$3:$C$475) >= I$23), 0), 0)), "")} | J27: {=IFERROR(INDEX(FORECAST!$D$3:$D$475, MATCH(1, INDEX((ISNUMBER(SEARCH($B27, FORECAST!$A$3:$A$475))) * (INT(FORECAST!$B$3:$B$475) <= J$23) * (INT(FORECAST!$C$3:$C$475) >= J$23), 0), 0)), "")} | ... AD27: {=IFERROR(INDEX(FORECAST!$D$3:$D$475, MATCH(1, INDEX((ISNUMBER(SEARCH($B27, FORECAST!$A$3:$A$475))) * (INT(FORECAST!$B$3:$B$475) <= AD$23) * (INT(FORECAST!$C$3:$C$475) >= AD$23), 0), 0)), "")} -> Garantizado | AJ27: =COUNTIF(C27:AD27,"Garantizado")/28 -> 0.17857143 | AL27: =COUNTIF(C24:AD30,"Garantizado")/COUNTA(C24:AD30) -> 0.12244898
B28: SUQUIA | C28: {=IFERROR(INDEX(FORECAST!$D$3:$D$475, MATCH(1, INDEX((ISNUMBER(SEARCH($B28, FORECAST!$A$3:$A$475))) * (INT(FORECAST!$B$3:$B$475) <= C$23) * (INT(FORECAST!$C$3:$C$475) >= C$23), 0), 0)), "")} | D28: {=IFERROR(INDEX(FORECAST!$D$3:$D$475, MATCH(1, INDEX((ISNUMBER(SEARCH($B28, FORECAST!$A$3:$A$475))) * (INT(FORECAST!$B$3:$B$475) <= D$23) * (INT(FORECAST!$C$3:$C$475) >= D$23), 0), 0)), "")} | E28: {=IFERROR(INDEX(FORECAST!$D$3:$D$475, MATCH(1, INDEX((ISNUMBER(SEARCH($B28, FORECAST!$A$3:$A$475))) * (INT(FORECAST!$B$3:$B$475) <= E$23) * (INT(FORECAST!$C$3:$C$475) >= E$23), 0), 0)), "")} | F28: {=IFERROR(INDEX(FORECAST!$D$3:$D$475, MATCH(1, INDEX((ISNUMBER(SEARCH($B28, FORECAST!$A$3:$A$475))) * (INT(FORECAST!$B$3:$B$475) <= F$23) * (INT(FORECAST!$C$3:$C$475) >= F$23), 0), 0)), "")} | G28: {=IFERROR(INDEX(FORECAST!$D$3:$D$475, MATCH(1, INDEX((ISNUMBER(SEARCH($B28, FORECAST!$A$3:$A$475))) * (INT(FORECAST!$B$3:$B$475) <= G$23) * (INT(FORECAST!$C$3:$C$475) >= G$23), 0), 0)), "")} | H28: {=IFERROR(INDEX(FORECAST!$D$3:$D$475, MATCH(1, INDEX((ISNUMBER(SEARCH($B28, FORECAST!$A$3:$A$475))) * (INT(FORECAST!$B$3:$B$475) <= H$23) * (INT(FORECAST!$C$3:$C$475) >= H$23), 0), 0)), "")} | I28: {=IFERROR(INDEX(FORECAST!$D$3:$D$475, MATCH(1, INDEX((ISNUMBER(SEARCH($B28, FORECAST!$A$3:$A$475))) * (INT(FORECAST!$B$3:$B$475) <= I$23) * (INT(FORECAST!$C$3:$C$475) >= I$23), 0), 0)), "")} | J28: {=IFERROR(INDEX(FORECAST!$D$3:$D$475, MATCH(1, INDEX((ISNUMBER(SEARCH($B28, FORECAST!$A$3:$A$475))) * (INT(FORECAST!$B$3:$B$475) <= J$23) * (INT(FORECAST!$C$3:$C$475) >= J$23), 0), 0)), "")} | ... AD28: {=IFERROR(INDEX(FORECAST!$D$3:$D$475, MATCH(1, INDEX((ISNUMBER(SEARCH($B28, FORECAST!$A$3:$A$475))) * (INT(FORECAST!$B$3:$B$475) <= AD$23) * (INT(FORECAST!$C$3:$C$475) >= AD$23), 0), 0)), "")} -> Garantizado | AJ28: =COUNTIF(C28:AD28,"Garantizado")/28 -> 0.071428571
B29: YACANTO | C29: {=IFERROR(INDEX(FORECAST!$D$3:$D$475, MATCH(1, INDEX((ISNUMBER(SEARCH($B29, FORECAST!$A$3:$A$475))) * (INT(FORECAST!$B$3:$B$475) <= C$23) * (INT(FORECAST!$C$3:$C$475) >= C$23), 0), 0)), "")} | D29: {=IFERROR(INDEX(FORECAST!$D$3:$D$475, MATCH(1, INDEX((ISNUMBER(SEARCH($B29, FORECAST!$A$3:$A$475))) * (INT(FORECAST!$B$3:$B$475) <= D$23) * (INT(FORECAST!$C$3:$C$475) >= D$23), 0), 0)), "")} | E29: {=IFERROR(INDEX(FORECAST!$D$3:$D$475, MATCH(1, INDEX((ISNUMBER(SEARCH($B29, FORECAST!$A$3:$A$475))) * (INT(FORECAST!$B$3:$B$475) <= E$23) * (INT(FORECAST!$C$3:$C$475) >= E$23), 0), 0)), "")} | F29: {=IFERROR(INDEX(FORECAST!$D$3:$D$475, MATCH(1, INDEX((ISNUMBER(SEARCH($B29, FORECAST!$A$3:$A$475))) * (INT(FORECAST!$B$3:$B$475) <= F$23) * (INT(FORECAST!$C$3:$C$475) >= F$23), 0), 0)), "")} | G29: {=IFERROR(INDEX(FORECAST!$D$3:$D$475, MATCH(1, INDEX((ISNUMBER(SEARCH($B29, FORECAST!$A$3:$A$475))) * (INT(FORECAST!$B$3:$B$475) <= G$23) * (INT(FORECAST!$C$3:$C$475) >= G$23), 0), 0)), "")} | H29: {=IFERROR(INDEX(FORECAST!$D$3:$D$475, MATCH(1, INDEX((ISNUMBER(SEARCH($B29, FORECAST!$A$3:$A$475))) * (INT(FORECAST!$B$3:$B$475) <= H$23) * (INT(FORECAST!$C$3:$C$475) >= H$23), 0), 0)), "")} -> Garantizado | I29: {=IFERROR(INDEX(FORECAST!$D$3:$D$475, MATCH(1, INDEX((ISNUMBER(SEARCH($B29, FORECAST!$A$3:$A$475))) * (INT(FORECAST!$B$3:$B$475) <= I$23) * (INT(FORECAST!$C$3:$C$475) >= I$23), 0), 0)), "")} -> Garantizado | J29: {=IFERROR(INDEX(FORECAST!$D$3:$D$475, MATCH(1, INDEX((ISNUMBER(SEARCH($B29, FORECAST!$A$3:$A$475))) * (INT(FORECAST!$B$3:$B$475) <= J$23) * (INT(FORECAST!$C$3:$C$475) >= J$23), 0), 0)), "")} | ... AD29: {=IFERROR(INDEX(FORECAST!$D$3:$D$475, MATCH(1, INDEX((ISNUMBER(SEARCH($B29, FORECAST!$A$3:$A$475))) * (INT(FORECAST!$B$3:$B$475) <= AD$23) * (INT(FORECAST!$C$3:$C$475) >= AD$23), 0), 0)), "")} -> Garantizado | AJ29: =COUNTIF(C29:AD29,"Garantizado")/28 -> 0.28571429
B30: LAS SIERRAS | C30: {=IFERROR(INDEX(FORECAST!$D$3:$D$475, MATCH(1, INDEX((ISNUMBER(SEARCH($B30, FORECAST!$A$3:$A$475))) * (INT(FORECAST!$B$3:$B$475) <= C$23) * (INT(FORECAST!$C$3:$C$475) >= C$23), 0), 0)), "")} | D30: {=IFERROR(INDEX(FORECAST!$D$3:$D$475, MATCH(1, INDEX((ISNUMBER(SEARCH($B30, FORECAST!$A$3:$A$475))) * (INT(FORECAST!$B$3:$B$475) <= D$23) * (INT(FORECAST!$C$3:$C$475) >= D$23), 0), 0)), "")} | E30: {=IFERROR(INDEX(FORECAST!$D$3:$D$475, MATCH(1, INDEX((ISNUMBER(SEARCH($B30, FORECAST!$A$3:$A$475))) * (INT(FORECAST!$B$3:$B$475) <= E$23) * (INT(FORECAST!$C$3:$C$475) >= E$23), 0), 0)), "")} | F30: {=IFERROR(INDEX(FORECAST!$D$3:$D$475, MATCH(1, INDEX((ISNUMBER(SEARCH($B30, FORECAST!$A$3:$A$475))) * (INT(FORECAST!$B$3:$B$475) <= F$23) * (INT(FORECAST!$C$3:$C$475) >= F$23), 0), 0)), "")} | G30: {=IFERROR(INDEX(FORECAST!$D$3:$D$475, MATCH(1, INDEX((ISNUMBER(SEARCH($B30, FORECAST!$A$3:$A$475))) * (INT(FORECAST!$B$3:$B$475) <= G$23) * (INT(FORECAST!$C$3:$C$475) >= G$23), 0), 0)), "")} | H30: {=IFERROR(INDEX(FORECAST!$D$3:$D$475, MATCH(1, INDEX((ISNUMBER(SEARCH($B30, FORECAST!$A$3:$A$475))) * (INT(FORECAST!$B$3:$B$475) <= H$23) * (INT(FORECAST!$C$3:$C$475) >= H$23), 0), 0)), "")} | I30: {=IFERROR(INDEX(FORECAST!$D$3:$D$475, MATCH(1, INDEX((ISNUMBER(SEARCH($B30, FORECAST!$A$3:$A$475))) * (INT(FORECAST!$B$3:$B$475) <= I$23) * (INT(FORECAST!$C$3:$C$475) >= I$23), 0), 0)), "")} | J30: {=IFERROR(INDEX(FORECAST!$D$3:$D$475, MATCH(1, INDEX((ISNUMBER(SEARCH($B30, FORECAST!$A$3:$A$475))) * (INT(FORECAST!$B$3:$B$475) <= J$23) * (INT(FORECAST!$C$3:$C$475) >= J$23), 0), 0)), "")} | ... AD30: {=IFERROR(INDEX(FORECAST!$D$3:$D$475, MATCH(1, INDEX((ISNUMBER(SEARCH($B30, FORECAST!$A$3:$A$475))) * (INT(FORECAST!$B$3:$B$475) <= AD$23) * (INT(FORECAST!$C$3:$C$475) >= AD$23), 0), 0)), "")} | AJ30: =COUNTIF(C30:AD30,"Garantizado")/28 -> 0.10714286
B31: SAN JAVIER | C31: {=IFERROR(INDEX(FORECAST!$D$3:$D$475, MATCH(1, INDEX((ISNUMBER(SEARCH($B31, FORECAST!$A$3:$A$475))) * (INT(FORECAST!$B$3:$B$475) <= C$23) * (INT(FORECAST!$C$3:$C$475) >= C$23), 0), 0)), "")} | D31: {=IFERROR(INDEX(FORECAST!$D$3:$D$475, MATCH(1, INDEX((ISNUMBER(SEARCH($B31, FORECAST!$A$3:$A$475))) * (INT(FORECAST!$B$3:$B$475) <= D$23) * (INT(FORECAST!$C$3:$C$475) >= D$23), 0), 0)), "")} | E31: {=IFERROR(INDEX(FORECAST!$D$3:$D$475, MATCH(1, INDEX((ISNUMBER(SEARCH($B31, FORECAST!$A$3:$A$475))) * (INT(FORECAST!$B$3:$B$475) <= E$23) * (INT(FORECAST!$C$3:$C$475) >= E$23), 0), 0)), "")} | F31: {=IFERROR(INDEX(FORECAST!$D$3:$D$475, MATCH(1, INDEX((ISNUMBER(SEARCH($B31, FORECAST!$A$3:$A$475))) * (INT(FORECAST!$B$3:$B$475) <= F$23) * (INT(FORECAST!$C$3:$C$475) >= F$23), 0), 0)), "")} | G31: {=IFERROR(INDEX(FORECAST!$D$3:$D$475, MATCH(1, INDEX((ISNUMBER(SEARCH($B31, FORECAST!$A$3:$A$475))) * (INT(FORECAST!$B$3:$B$475) <= G$23) * (INT(FORECAST!$C$3:$C$475) >= G$23), 0), 0)), "")} | H31: {=IFERROR(INDEX(FORECAST!$D$3:$D$475, MATCH(1, INDEX((ISNUMBER(SEARCH($B31, FORECAST!$A$3:$A$475))) * (INT(FORECAST!$B$3:$B$475) <= H$23) * (INT(FORECAST!$C$3:$C$475) >= H$23), 0), 0)), "")} | I31: {=IFERROR(INDEX(FORECAST!$D$3:$D$475, MATCH(1, INDEX((ISNUMBER(SEARCH($B31, FORECAST!$A$3:$A$475))) * (INT(FORECAST!$B$3:$B$475) <= I$23) * (INT(FORECAST!$C$3:$C$475) >= I$23), 0), 0)), "")} | J31: {=IFERROR(INDEX(FORECAST!$D$3:$D$475, MATCH(1, INDEX((ISNUMBER(SEARCH($B31, FORECAST!$A$3:$A$475))) * (INT(FORECAST!$B$3:$B$475) <= J$23) * (INT(FORECAST!$C$3:$C$475) >= J$23), 0), 0)), "")} | ... AD31: {=IFERROR(INDEX(FORECAST!$D$3:$D$475, MATCH(1, INDEX((ISNUMBER(SEARCH($B31, FORECAST!$A$3:$A$475))) * (INT(FORECAST!$B$3:$B$475) <= AD$23) * (INT(FORECAST!$C$3:$C$475) >= AD$23), 0), 0)), "")} | AJ31: =COUNTIF(C31:AD31,"Garantizado")/28 -> 0
C33: DO | D33: LU | E33: MA | F33: MI | G33: JU | H33: VI | I33: SA | J33: DO | K33: LU | L33: MA | M33: MI | N33: JU | O33: VI | P33: SA | Q33: DO | R33: LU | S33: MA | T33: MI | U33: JU | V33: VI | W33: SÁ. | X33: DO. | Y33: LU. | Z33: MA. | AA33: MI. | AB33: JU. | AC33: VI. | AD33: SÁ. | AE33: DO. | AF33: LU. | AG33: MA.
C34: 46082 | D34: 46083 | E34: 46084 | F34: 46085 | G34: 46086 | H34: 46087 | I34: 46088 | J34: 46089 | K34: 46090 | L34: 46091 | M34: 46092 | N34: 46093 | O34: 46094 | P34: 46095 | Q34: 46096 | R34: 46097 | S34: 46098 | T34: 46099 | U34: 46100 | V34: 46101 | W34: 46102 | X34: 46103 | Y34: 46104 | Z34: 46105 | AA34: 46106 | AB34: 46107 | AC34: 46108 | AD34: 46109 | AE34: 46110 | AF34: 46111 | AG34: 46112 | AJ34: Ocupación
A35: MARZO | B35: LUGONES | C35: {=IFERROR(INDEX(FORECAST!$D$12:$D$475, MATCH(1, INDEX((ISNUMBER(SEARCH($B35, FORECAST!$A$12:$A$475))) * (INT(FORECAST!$B$12:$B$475) <= C$34) * (INT(FORECAST!$C$12:$C$475) >= C$34), 0), 0)), "")} | D35: {=IFERROR(INDEX(FORECAST!$D$12:$D$475, MATCH(1, INDEX((ISNUMBER(SEARCH($B35, FORECAST!$A$12:$A$475))) * (INT(FORECAST!$B$12:$B$475) <= D$34) * (INT(FORECAST!$C$12:$C$475) >= D$34), 0), 0)), "")} | E35: {=IFERROR(INDEX(FORECAST!$D$12:$D$475, MATCH(1, INDEX((ISNUMBER(SEARCH($B35, FORECAST!$A$12:$A$475))) * (INT(FORECAST!$B$12:$B$475) <= E$34) * (INT(FORECAST!$C$12:$C$475) >= E$34), 0), 0)), "")} | F35: {=IFERROR(INDEX(FORECAST!$D$12:$D$475, MATCH(1, INDEX((ISNUMBER(SEARCH($B35, FORECAST!$A$12:$A$475))) * (INT(FORECAST!$B$12:$B$475) <= F$34) * (INT(FORECAST!$C$12:$C$475) >= F$34), 0), 0)), "")} | G35: {=IFERROR(INDEX(FORECAST!$D$12:$D$475, MATCH(1, INDEX((ISNUMBER(SEARCH($B35, FORECAST!$A$12:$A$475))) * (INT(FORECAST!$B$12:$B$475) <= G$34) * (INT(FORECAST!$C$12:$C$475) >= G$34), 0), 0)), "")} | H35: {=IFERROR(INDEX(FORECAST!$D$12:$D$475, MATCH(1, INDEX((ISNUMBER(SEARCH($B35, FORECAST!$A$12:$A$475))) * (INT(FORECAST!$B$12:$B$475) <= H$34) * (INT(FORECAST!$C$12:$C$475) >= H$34), 0), 0)), "")} | I35: {=IFERROR(INDEX(FORECAST!$D$12:$D$475, MATCH(1, INDEX((ISNUMBER(SEARCH($B35, FORECAST!$A$12:$A$475))) * (INT(FORECAST!$B$12:$B$475) <= I$34) * (INT(FORECAST!$C$12:$C$475) >= I$34), 0), 0)), "")} -> Garantizado | J35: {=IFERROR(INDEX(FORECAST!$D$12:$D$475, MATCH(1, INDEX((ISNUMBER(SEARCH($B35, FORECAST!$A$12:$A$475))) * (INT(FORECAST!$B$12:$B$475) <= J$34) * (INT(FORECAST!$C$12:$C$475) >= J$34), 0), 0)), "")} -> Garantizado | ... AG35: {=IFERROR(INDEX(FORECAST!$D$12:$D$475, MATCH(1, INDEX((ISNUMBER(SEARCH($B35, FORECAST!$A$12:$A$475))) * (INT(FORECAST!$B$12:$B$475) <= AG$34) * (INT(FORECAST!$C$12:$C$475) >= AG$34), 0), 0)), "")} | AJ35: =COUNTIF(C35:AG35,"Garantizado")/31 -> 0.41935484
B36: CHAMPAQUI | C36: {=IFERROR(INDEX(FORECAST!$D$12:$D$475, MATCH(1, INDEX((ISNUMBER(SEARCH($B36, FORECAST!$A$12:$A$475))) * (INT(FORECAST!$B$12:$B$475) <= C$34) * (INT(FORECAST!$C$12:$C$475) >= C$34), 0), 0)), "")} | D36: {=IFERROR(INDEX(FORECAST!$D$12:$D$475, MATCH(1, INDEX((ISNUMBER(SEARCH($B36, FORECAST!$A$12:$A$475))) * (INT(FORECAST!$B$12:$B$475) <= D$34) * (INT(FORECAST!$C$12:$C$475) >= D$34), 0), 0)), "")} | E36: {=IFERROR(INDEX(FORECAST!$D$12:$D$475, MATCH(1, INDEX((ISNUMBER(SEARCH($B36, FORECAST!$A$12:$A$475))) * (INT(FORECAST!$B$12:$B$475) <= E$34) * (INT(FORECAST!$C$12:$C$475) >= E$34), 0), 0)), "")} | F36: {=IFERROR(INDEX(FORECAST!$D$12:$D$475, MATCH(1, INDEX((ISNUMBER(SEARCH($B36, FORECAST!$A$12:$A$475))) * (INT(FORECAST!$B$12:$B$475) <= F$34) * (INT(FORECAST!$C$12:$C$475) >= F$34), 0), 0)), "")} | G36: {=IFERROR(INDEX(FORECAST!$D$12:$D$475, MATCH(1, INDEX((ISNUMBER(SEARCH($B36, FORECAST!$A$12:$A$475))) * (INT(FORECAST!$B$12:$B$475) <= G$34) * (INT(FORECAST!$C$12:$C$475) >= G$34), 0), 0)), "")} | H36: {=IFERROR(INDEX(FORECAST!$D$12:$D$475, MATCH(1, INDEX((ISNUMBER(SEARCH($B36, FORECAST!$A$12:$A$475))) * (INT(FORECAST!$B$12:$B$475) <= H$34) * (INT(FORECAST!$C$12:$C$475) >= H$34), 0), 0)), "")} | I36: {=IFERROR(INDEX(FORECAST!$D$12:$D$475, MATCH(1, INDEX((ISNUMBER(SEARCH($B36, FORECAST!$A$12:$A$475))) * (INT(FORECAST!$B$12:$B$475) <= I$34) * (INT(FORECAST!$C$12:$C$475) >= I$34), 0), 0)), "")} -> Garantizado | J36: {=IFERROR(INDEX(FORECAST!$D$12:$D$475, MATCH(1, INDEX((ISNUMBER(SEARCH($B36, FORECAST!$A$12:$A$475))) * (INT(FORECAST!$B$12:$B$475) <= J$34) * (INT(FORECAST!$C$12:$C$475) >= J$34), 0), 0)), "")} -> Garantizado | ... AG36: {=IFERROR(INDEX(FORECAST!$D$12:$D$475, MATCH(1, INDEX((ISNUMBER(SEARCH($B36, FORECAST!$A$12:$A$475))) * (INT(FORECAST!$B$12:$B$475) <= AG$34) * (INT(FORECAST!$C$12:$C$475) >= AG$34), 0), 0)), "")} | AJ36: =COUNTIF(C36:AG36,"Garantizado")/31 -> 0.38709677 | AL36: Ocupación Mensual Total
B37: TERRAZA | C37: {=IFERROR(INDEX(FORECAST!$D$12:$D$475, MATCH(1, INDEX((ISNUMBER(SEARCH($B37, FORECAST!$A$12:$A$475))) * (INT(FORECAST!$B$12:$B$475) <= C$34) * (INT(FORECAST!$C$12:$C$475) >= C$34), 0), 0)), "")} | D37: {=IFERROR(INDEX(FORECAST!$D$12:$D$475, MATCH(1, INDEX((ISNUMBER(SEARCH($B37, FORECAST!$A$12:$A$475))) * (INT(FORECAST!$B$12:$B$475) <= D$34) * (INT(FORECAST!$C$12:$C$475) >= D$34), 0), 0)), "")} | E37: {=IFERROR(INDEX(FORECAST!$D$12:$D$475, MATCH(1, INDEX((ISNUMBER(SEARCH($B37, FORECAST!$A$12:$A$475))) * (INT(FORECAST!$B$12:$B$475) <= E$34) * (INT(FORECAST!$C$12:$C$475) >= E$34), 0), 0)), "")} | F37: {=IFERROR(INDEX(FORECAST!$D$12:$D$475, MATCH(1, INDEX((ISNUMBER(SEARCH($B37, FORECAST!$A$12:$A$475))) * (INT(FORECAST!$B$12:$B$475) <= F$34) * (INT(FORECAST!$C$12:$C$475) >= F$34), 0), 0)), "")} | G37: {=IFERROR(INDEX(FORECAST!$D$12:$D$475, MATCH(1, INDEX((ISNUMBER(SEARCH($B37, FORECAST!$A$12:$A$475))) * (INT(FORECAST!$B$12:$B$475) <= G$34) * (INT(FORECAST!$C$12:$C$475) >= G$34), 0), 0)), "")} | H37: {=IFERROR(INDEX(FORECAST!$D$12:$D$475, MATCH(1, INDEX((ISNUMBER(SEARCH($B37, FORECAST!$A$12:$A$475))) * (INT(FORECAST!$B$12:$B$475) <= H$34) * (INT(FORECAST!$C$12:$C$475) >= H$34), 0), 0)), "")} | I37: {=IFERROR(INDEX(FORECAST!$D$12:$D$475, MATCH(1, INDEX((ISNUMBER(SEARCH($B37, FORECAST!$A$12:$A$475))) * (INT(FORECAST!$B$12:$B$475) <= I$34) * (INT(FORECAST!$C$12:$C$475) >= I$34), 0), 0)), "")} -> Garantizado | J37: {=IFERROR(INDEX(FORECAST!$D$12:$D$475, MATCH(1, INDEX((ISNUMBER(SEARCH($B37, FORECAST!$A$12:$A$475))) * (INT(FORECAST!$B$12:$B$475) <= J$34) * (INT(FORECAST!$C$12:$C$475) >= J$34), 0), 0)), "")} -> Garantizado | ... AG37: {=IFERROR(INDEX(FORECAST!$D$12:$D$475, MATCH(1, INDEX((ISNUMBER(SEARCH($B37, FORECAST!$A$12:$A$475))) * (INT(FORECAST!$B$12:$B$475) <= AG$34) * (INT(FORECAST!$C$12:$C$475) >= AG$34), 0), 0)), "")} | AJ37: =COUNTIF(C37:AG37,"Garantizado")/31 -> 0.29032258 | AL37: =COUNTIF('PLANNING 2026'!C35:AG41,"Garantizado")/COUNTA('PLANNING 2026'!C35:AG41) -> 0.38709677
B38: URITORCO | C38: {=IFERROR(INDEX(FORECAST!$D$12:$D$475, MATCH(1, INDEX((ISNUMBER(SEARCH($B38, FORECAST!$A$12:$A$475))) * (INT(FORECAST!$B$12:$B$475) <= C$34) * (INT(FORECAST!$C$12:$C$475) >= C$34), 0), 0)), "")} | D38: {=IFERROR(INDEX(FORECAST!$D$12:$D$475, MATCH(1, INDEX((ISNUMBER(SEARCH($B38, FORECAST!$A$12:$A$475))) * (INT(FORECAST!$B$12:$B$475) <= D$34) * (INT(FORECAST!$C$12:$C$475) >= D$34), 0), 0)), "")} | E38: {=IFERROR(INDEX(FORECAST!$D$12:$D$475, MATCH(1, INDEX((ISNUMBER(SEARCH($B38, FORECAST!$A$12:$A$475))) * (INT(FORECAST!$B$12:$B$475) <= E$34) * (INT(FORECAST!$C$12:$C$475) >= E$34), 0), 0)), "")} | F38: {=IFERROR(INDEX(FORECAST!$D$12:$D$475, MATCH(1, INDEX((ISNUMBER(SEARCH($B38, FORECAST!$A$12:$A$475))) * (INT(FORECAST!$B$12:$B$475) <= F$34) * (INT(FORECAST!$C$12:$C$475) >= F$34), 0), 0)), "")} | G38: {=IFERROR(INDEX(FORECAST!$D$12:$D$475, MATCH(1, INDEX((ISNUMBER(SEARCH($B38, FORECAST!$A$12:$A$475))) * (INT(FORECAST!$B$12:$B$475) <= G$34) * (INT(FORECAST!$C$12:$C$475) >= G$34), 0), 0)), "")} | H38: {=IFERROR(INDEX(FORECAST!$D$12:$D$475, MATCH(1, INDEX((ISNUMBER(SEARCH($B38, FORECAST!$A$12:$A$475))) * (INT(FORECAST!$B$12:$B$475) <= H$34) * (INT(FORECAST!$C$12:$C$475) >= H$34), 0), 0)), "")} | I38: {=IFERROR(INDEX(FORECAST!$D$12:$D$475, MATCH(1, INDEX((ISNUMBER(SEARCH($B38, FORECAST!$A$12:$A$475))) * (INT(FORECAST!$B$12:$B$475) <= I$34) * (INT(FORECAST!$C$12:$C$475) >= I$34), 0), 0)), "")} -> Garantizado | J38: {=IFERROR(INDEX(FORECAST!$D$12:$D$475, MATCH(1, INDEX((ISNUMBER(SEARCH($B38, FORECAST!$A$12:$A$475))) * (INT(FORECAST!$B$12:$B$475) <= J$34) * (INT(FORECAST!$C$12:$C$475) >= J$34), 0), 0)), "")} -> Garantizado | ... AG38: {=IFERROR(INDEX(FORECAST!$D$12:$D$475, MATCH(1, INDEX((ISNUMBER(SEARCH($B38, FORECAST!$A$12:$A$475))) * (INT(FORECAST!$B$12:$B$475) <= AG$34) * (INT(FORECAST!$C$12:$C$475) >= AG$34), 0), 0)), "")} | AJ38: =COUNTIF(C38:AG38,"Garantizado")/31 -> 0.4516129
B39: SUQUIA | C39: {=IFERROR(INDEX(FORECAST!$D$12:$D$475, MATCH(1, INDEX((ISNUMBER(SEARCH($B39, FORECAST!$A$12:$A$475))) * (INT(FORECAST!$B$12:$B$475) <= C$34) * (INT(FORECAST!$C$12:$C$475) >= C$34), 0), 0)), "")} | D39: {=IFERROR(INDEX(FORECAST!$D$12:$D$475, MATCH(1, INDEX((ISNUMBER(SEARCH($B39, FORECAST!$A$12:$A$475))) * (INT(FORECAST!$B$12:$B$475) <= D$34) * (INT(FORECAST!$C$12:$C$475) >= D$34), 0), 0)), "")} | E39: {=IFERROR(INDEX(FORECAST!$D$12:$D$475, MATCH(1, INDEX((ISNUMBER(SEARCH($B39, FORECAST!$A$12:$A$475))) * (INT(FORECAST!$B$12:$B$475) <= E$34) * (INT(FORECAST!$C$12:$C$475) >= E$34), 0), 0)), "")} | F39: {=IFERROR(INDEX(FORECAST!$D$12:$D$475, MATCH(1, INDEX((ISNUMBER(SEARCH($B39, FORECAST!$A$12:$A$475))) * (INT(FORECAST!$B$12:$B$475) <= F$34) * (INT(FORECAST!$C$12:$C$475) >= F$34), 0), 0)), "")} | G39: {=IFERROR(INDEX(FORECAST!$D$12:$D$475, MATCH(1, INDEX((ISNUMBER(SEARCH($B39, FORECAST!$A$12:$A$475))) * (INT(FORECAST!$B$12:$B$475) <= G$34) * (INT(FORECAST!$C$12:$C$475) >= G$34), 0), 0)), "")} -> Garantizado | H39: {=IFERROR(INDEX(FORECAST!$D$12:$D$475, MATCH(1, INDEX((ISNUMBER(SEARCH($B39, FORECAST!$A$12:$A$475))) * (INT(FORECAST!$B$12:$B$475) <= H$34) * (INT(FORECAST!$C$12:$C$475) >= H$34), 0), 0)), "")} -> Garantizado | I39: {=IFERROR(INDEX(FORECAST!$D$12:$D$475, MATCH(1, INDEX((ISNUMBER(SEARCH($B39, FORECAST!$A$12:$A$475))) * (INT(FORECAST!$B$12:$B$475) <= I$34) * (INT(FORECAST!$C$12:$C$475) >= I$34), 0), 0)), "")} -> Garantizado | J39: {=IFERROR(INDEX(FORECAST!$D$12:$D$475, MATCH(1, INDEX((ISNUMBER(SEARCH($B39, FORECAST!$A$12:$A$475))) * (INT(FORECAST!$B$12:$B$475) <= J$34) * (INT(FORECAST!$C$12:$C$475) >= J$34), 0), 0)), "")} -> Garantizado | ... AG39: {=IFERROR(INDEX(FORECAST!$D$12:$D$475, MATCH(1, INDEX((ISNUMBER(SEARCH($B39, FORECAST!$A$12:$A$475))) * (INT(FORECAST!$B$12:$B$475) <= AG$34) * (INT(FORECAST!$C$12:$C$475) >= AG$34), 0), 0)), "")} | AJ39: =COUNTIF(C39:AG39,"Garantizado")/31 -> 0.48387097
B40: YACANTO | C40: {=IFERROR(INDEX(FORECAST!$D$12:$D$475, MATCH(1, INDEX((ISNUMBER(SEARCH($B40, FORECAST!$A$12:$A$475))) * (INT(FORECAST!$B$12:$B$475) <= C$34) * (INT(FORECAST!$C$12:$C$475) >= C$34), 0), 0)), "")} -> Garantizado | D40: {=IFERROR(INDEX(FORECAST!$D$12:$D$475, MATCH(1, INDEX((ISNUMBER(SEARCH($B40, FORECAST!$A$12:$A$475))) * (INT(FORECAST!$B$12:$B$475) <= D$34) * (INT(FORECAST!$C$12:$C$475) >= D$34), 0), 0)), "")} -> Garantizado | E40: {=IFERROR(INDEX(FORECAST!$D$12:$D$475, MATCH(1, INDEX((ISNUMBER(SEARCH($B40, FORECAST!$A$12:$A$475))) * (INT(FORECAST!$B$12:$B$475) <= E$34) * (INT(FORECAST!$C$12:$C$475) >= E$34), 0), 0)), "")} -> Garantizado | F40: {=IFERROR(INDEX(FORECAST!$D$12:$D$475, MATCH(1, INDEX((ISNUMBER(SEARCH($B40, FORECAST!$A$12:$A$475))) * (INT(FORECAST!$B$12:$B$475) <= F$34) * (INT(FORECAST!$C$12:$C$475) >= F$34), 0), 0)), "")} | G40: {=IFERROR(INDEX(FORECAST!$D$12:$D$475, MATCH(1, INDEX((ISNUMBER(SEARCH($B40, FORECAST!$A$12:$A$475))) * (INT(FORECAST!$B$12:$B$475) <= G$34) * (INT(FORECAST!$C$12:$C$475) >= G$34), 0), 0)), "")} | H40: {=IFERROR(INDEX(FORECAST!$D$12:$D$475, MATCH(1, INDEX((ISNUMBER(SEARCH($B40, FORECAST!$A$12:$A$475))) * (INT(FORECAST!$B$12:$B$475) <= H$34) * (INT(FORECAST!$C$12:$C$475) >= H$34), 0), 0)), "")} | I40: {=IFERROR(INDEX(FORECAST!$D$12:$D$475, MATCH(1, INDEX((ISNUMBER(SEARCH($B40, FORECAST!$A$12:$A$475))) * (INT(FORECAST!$B$12:$B$475) <= I$34) * (INT(FORECAST!$C$12:$C$475) >= I$34), 0), 0)), "")} | J40: {=IFERROR(INDEX(FORECAST!$D$12:$D$475, MATCH(1, INDEX((ISNUMBER(SEARCH($B40, FORECAST!$A$12:$A$475))) * (INT(FORECAST!$B$12:$B$475) <= J$34) * (INT(FORECAST!$C$12:$C$475) >= J$34), 0), 0)), "")} | ... AG40: {=IFERROR(INDEX(FORECAST!$D$12:$D$475, MATCH(1, INDEX((ISNUMBER(SEARCH($B40, FORECAST!$A$12:$A$475))) * (INT(FORECAST!$B$12:$B$475) <= AG$34) * (INT(FORECAST!$C$12:$C$475) >= AG$34), 0), 0)), "")} -> Presupuesto | AJ40: =COUNTIF(C40:AG40,"Garantizado")/31 -> 0.38709677
B41: LAS SIERRAS | C41: {=IFERROR(INDEX(FORECAST!$D$12:$D$475, MATCH(1, INDEX((ISNUMBER(SEARCH($B41, FORECAST!$A$12:$A$475))) * (INT(FORECAST!$B$12:$B$475) <= C$34) * (INT(FORECAST!$C$12:$C$475) >= C$34), 0), 0)), "")} | D41: {=IFERROR(INDEX(FORECAST!$D$12:$D$475, MATCH(1, INDEX((ISNUMBER(SEARCH($B41, FORECAST!$A$12:$A$475))) * (INT(FORECAST!$B$12:$B$475) <= D$34) * (INT(FORECAST!$C$12:$C$475) >= D$34), 0), 0)), "")} | E41: {=IFERROR(INDEX(FORECAST!$D$12:$D$475, MATCH(1, INDEX((ISNUMBER(SEARCH($B41, FORECAST!$A$12:$A$475))) * (INT(FORECAST!$B$12:$B$475) <= E$34) * (INT(FORECAST!$C$12:$C$475) >= E$34), 0), 0)), "")} -> Garantizado | F41: {=IFERROR(INDEX(FORECAST!$D$12:$D$475, MATCH(1, INDEX((ISNUMBER(SEARCH($B41, FORECAST!$A$12:$A$475))) * (INT(FORECAST!$B$12:$B$475) <= F$34) * (INT(FORECAST!$C$12:$C$475) >= F$34), 0), 0)), "")} -> Garantizado | G41: {=IFERROR(INDEX(FORECAST!$D$12:$D$475, MATCH(1, INDEX((ISNUMBER(SEARCH($B41, FORECAST!$A$12:$A$475))) * (INT(FORECAST!$B$12:$B$475) <= G$34) * (INT(FORECAST!$C$12:$C$475) >= G$34), 0), 0)), "")} | H41: {=IFERROR(INDEX(FORECAST!$D$12:$D$475, MATCH(1, INDEX((ISNUMBER(SEARCH($B41, FORECAST!$A$12:$A$475))) * (INT(FORECAST!$B$12:$B$475) <= H$34) * (INT(FORECAST!$C$12:$C$475) >= H$34), 0), 0)), "")} | I41: {=IFERROR(INDEX(FORECAST!$D$12:$D$475, MATCH(1, INDEX((ISNUMBER(SEARCH($B41, FORECAST!$A$12:$A$475))) * (INT(FORECAST!$B$12:$B$475) <= I$34) * (INT(FORECAST!$C$12:$C$475) >= I$34), 0), 0)), "")} | J41: {=IFERROR(INDEX(FORECAST!$D$12:$D$475, MATCH(1, INDEX((ISNUMBER(SEARCH($B41, FORECAST!$A$12:$A$475))) * (INT(FORECAST!$B$12:$B$475) <= J$34) * (INT(FORECAST!$C$12:$C$475) >= J$34), 0), 0)), "")} | ... AG41: {=IFERROR(INDEX(FORECAST!$D$12:$D$475, MATCH(1, INDEX((ISNUMBER(SEARCH($B41, FORECAST!$A$12:$A$475))) * (INT(FORECAST!$B$12:$B$475) <= AG$34) * (INT(FORECAST!$C$12:$C$475) >= AG$34), 0), 0)), "")} | AJ41: =COUNTIF(C41:AG41,"Garantizado")/31 -> 0.29032258
B42: SAN JAVIER | C42: {=IFERROR(INDEX(FORECAST!$D$12:$D$475, MATCH(1, INDEX((ISNUMBER(SEARCH($B42, FORECAST!$A$12:$A$475))) * (INT(FORECAST!$B$12:$B$475) <= C$34) * (INT(FORECAST!$C$12:$C$475) >= C$34), 0), 0)), "")} | D42: {=IFERROR(INDEX(FORECAST!$D$12:$D$475, MATCH(1, INDEX((ISNUMBER(SEARCH($B42, FORECAST!$A$12:$A$475))) * (INT(FORECAST!$B$12:$B$475) <= D$34) * (INT(FORECAST!$C$12:$C$475) >= D$34), 0), 0)), "")} | E42: {=IFERROR(INDEX(FORECAST!$D$12:$D$475, MATCH(1, INDEX((ISNUMBER(SEARCH($B42, FORECAST!$A$12:$A$475))) * (INT(FORECAST!$B$12:$B$475) <= E$34) * (INT(FORECAST!$C$12:$C$475) >= E$34), 0), 0)), "")} | F42: {=IFERROR(INDEX(FORECAST!$D$12:$D$475, MATCH(1, INDEX((ISNUMBER(SEARCH($B42, FORECAST!$A$12:$A$475))) * (INT(FORECAST!$B$12:$B$475) <= F$34) * (INT(FORECAST!$C$12:$C$475) >= F$34), 0), 0)), "")} | G42: {=IFERROR(INDEX(FORECAST!$D$12:$D$475, MATCH(1, INDEX((ISNUMBER(SEARCH($B42, FORECAST!$A$12:$A$475))) * (INT(FORECAST!$B$12:$B$475) <= G$34) * (INT(FORECAST!$C$12:$C$475) >= G$34), 0), 0)), "")} | H42: {=IFERROR(INDEX(FORECAST!$D$12:$D$475, MATCH(1, INDEX((ISNUMBER(SEARCH($B42, FORECAST!$A$12:$A$475))) * (INT(FORECAST!$B$12:$B$475) <= H$34) * (INT(FORECAST!$C$12:$C$475) >= H$34), 0), 0)), "")} -> Garantizado | I42: {=IFERROR(INDEX(FORECAST!$D$12:$D$475, MATCH(1, INDEX((ISNUMBER(SEARCH($B42, FORECAST!$A$12:$A$475))) * (INT(FORECAST!$B$12:$B$475) <= I$34) * (INT(FORECAST!$C$12:$C$475) >= I$34), 0), 0)), "")} -> Garantizado | J42: {=IFERROR(INDEX(FORECAST!$D$12:$D$475, MATCH(1, INDEX((ISNUMBER(SEARCH($B42, FORECAST!$A$12:$A$475))) * (INT(FORECAST!$B$12:$B$475) <= J$34) * (INT(FORECAST!$C$12:$C$475) >= J$34), 0), 0)), "")} -> Garantizado | ... AG42: {=IFERROR(INDEX(FORECAST!$D$12:$D$475, MATCH(1, INDEX((ISNUMBER(SEARCH($B42, FORECAST!$A$12:$A$475))) * (INT(FORECAST!$B$12:$B$475) <= AG$34) * (INT(FORECAST!$C$12:$C$475) >= AG$34), 0), 0)), "")} | AJ42: =COUNTIF(C42:AG42,"Garantizado")/31 -> 0.32258065
AE43: {=IFERROR(INDEX(FORECAST!$E$12:$E$475, MATCH(1, INDEX((ISNUMBER(SEARCH($C43, FORECAST!$A$12:$A$475))) * (FORECAST!$B$12:$B$475 <= AE$37) * (FORECAST!$C$12:$C$475 >= AE$37), 0), 0)), "")} | AF43: {=IFERROR(INDEX(FORECAST!$E$12:$E$475, MATCH(1, INDEX((ISNUMBER(SEARCH($C43, FORECAST!$A$12:$A$475))) * (FORECAST!$B$12:$B$475 <= AF$37) * (FORECAST!$C$12:$C$475 >= AF$37), 0), 0)), "")} | AG43: {=IFERROR(INDEX(FORECAST!$E$12:$E$475, MATCH(1, INDEX((ISNUMBER(SEARCH($C43, FORECAST!$A$12:$A$475))) * (FORECAST!$B$12:$B$475 <= AG$37) * (FORECAST!$C$12:$C$475 >= AG$37), 0), 0)), "")} | AH43: {=IFERROR(INDEX(FORECAST!$E$12:$E$475, MATCH(1, INDEX((ISNUMBER(SEARCH($C43, FORECAST!$A$12:$A$475))) * (FORECAST!$B$12:$B$475 <= AH$37) * (FORECAST!$C$12:$C$475 >= AH$37), 0), 0)), "")}
AH44: {=IFERROR(INDEX(FORECAST!$E$12:$E$475, MATCH(1, INDEX((ISNUMBER(SEARCH($C44, FORECAST!$A$12:$A$475))) * (FORECAST!$B$12:$B$475 <= AH$37) * (FORECAST!$C$12:$C$475 >= AH$37), 0), 0)), "")}
C45: MI | D45: JU | E45: VI | F45: SA | G45: DO | H45: LU | I45: MA | J45: MI | K45: JU | L45: VI | M45: SA | N45: DO | O45: LU | P45: MA | Q45: MI | R45: JU | S45: VI | T45: SÁ. | U45: DO. | V45: LU. | W45: MA. | X45: MI. | Y45: JU. | Z45: VI. | AA45: SÁ. | AB45: DO. | AC45: LU. | AD45: MA. | AE45: MI. | AF45: JU. | AH45: {=IFERROR(INDEX(FORECAST!$E$12:$E$475, MATCH(1, INDEX((ISNUMBER(SEARCH(#REF!, FORECAST!$A$12:$A$475))) * (FORECAST!$B$12:$B$475 <= AH$37) * (FORECAST!$C$12:$C$475 >= AH$37), 0), 0)), "")}
...

Sheet ROOM RENTAL PROYECTADO
B2: MES | C2: TOTAL ROOM RENTAL RACK | D2: ROOM RENTAL PROYECTADO | E2: PORCENTAJE VENDIDO (Sobre total Rack) | F2: PORCENTAJE OCUPADO | G2: REVPAR
B3: ENERO | C3: 587450 | D3: =SUMIFS(FORECAST!G3:G71,FORECAST!B3:B71, ">="&"01/01/2026",FORECAST!B3:B71, "<="&"31/01/2026") -> 0 | E3: =D3/C3 -> 0 | F3: =COUNTIF('PLANNING 2026'!C13:AG19,"Garantizado")/COUNTA('PLANNING 2026'!C13:AG19) -> 0.069124424 | G3: 0
B4: FEBRERO | C4: 530600 | D4: =SUMIFS(FORECAST!G4:G72,FORECAST!B4:B72, ">="&"01/02/2026",FORECAST!B4:B72, "<="&"28/02/2026") -> 963 | E4: =D4/C4 -> 0.0018149265 | F4: =COUNTIF('PLANNING 2026'!C24:AD30,"Garantizado")/COUNTA('PLANNING 2026'!C24:AD30) -> 0.12244898 | G4: =D4/(7*28) -> 4.9132653
B5: MARZO | C5: 587450 | D5: =SUMIFS(FORECAST!G5:G493,FORECAST!B5:B493, ">="&"01/03/2026",FORECAST!B5:B493, "<="&"31/03/2026") -> 54348 | E5: =D5/C5 -> 0.092515108 | F5: =COUNTIF('PLANNING 2026'!C35:AG41,"Garantizado")/COUNTA('PLANNING 2026'!C35:AG41) -> 0.38709677 | G5: =D5/(7*31) -> 250.45161
B6: ABRIL | C6: 568500 | D6: =SUMIFS(FORECAST!G6:G293,FORECAST!B6:B293, ">="&"01/04/2026",FORECAST!B6:B293, "<="&"30/04/2026") -> 59975 | E6: =D6/C6 -> 0.10549692 | F6: =COUNTIF('PLANNING 2026'!C33:AF53,"Garantizado")/COUNTA('PLANNING 2026'!C33:AF53) -> 0.26748252 | G6: =D6/(7*30) -> 285.59524
B7: MAYO | C7: 587450 | D7: =SUMIFS(FORECAST!G7:G593,FORECAST!B7:B593, ">="&"01/05/2026",FORECAST!B7:B593, "<="&"30/05/2026") -> 101000 | E7: =D7/C7 -> 0.17192953 | F7: =COUNTIF('PLANNING 2026'!C58:AG64,"Garantizado")/COUNTA('PLANNING 2026'!C58:AG64) -> 0.22580645 | G7: =D7/(7*31) -> 465.43779
B8: JUNIO | C8: 568500 | D8: =SUMIFS(FORECAST!G8:G593,FORECAST!B8:B593, ">="&"01/06/2026",FORECAST!B8:B593, "<="&"30/06/2026") -> 72740 | E8: =D8/C8 -> 0.12795075 | F8: =COUNTIF('PLANNING 2026'!C70:AF76,"Garantizado")/COUNTA('PLANNING 2026'!C70:AF76) -> 0.2047619 | G8: =D8/(7*30) -> 346.38095
B9: JULIO | C9: 587450 | D9: =SUMIFS(FORECAST!G9:G593,FORECAST!B9:B593, ">="&"01/07/2026",FORECAST!B9:B593, "<="&"30/07/2026") -> 3000 | E9: =D9/C9 -> 0.0051068176 | F9: =COUNTIF('PLANNING 2026'!C82:AG88,"Garantizado")/COUNTA('PLANNING 2026'!C82:AG88) -> 0.013824885 | G9: =D9/(7*31) -> 13.824885
B10: AGOSTO | C10: 587450 | D10: =SUMIFS(FORECAST!G9:G593,FORECAST!B9:B593, ">="&"01/08/2026",FORECAST!B9:B593, "<="&"30/08/2026") -> 18000 | E10: =D10/C10 -> 0.030640906 | F10: =COUNTIF('PLANNING 2026'!C90:AG100,"Garantizado")/COUNTA('PLANNING 2026'!C90:AG100) -> 0.09929078 | G10: =D10/(7*31) -> 82.949309
B11: SEPTIEMBRE | C11: 568500 | D11: =SUMIFS(FORECAST!G10:G601,FORECAST!B10:B601, ">="&"01/09/2026",FORECAST!B10:B601, "<="&"30/09/2026") -> 129000 | E11: =D11/C11 -> 0.22691293 | F11: =COUNTIF('PLANNING 2026'!C105:AF111,"Garantizado")/COUNTA('PLANNING 2026'!C105:AF111) -> 0.47142857 | G11: =D11/(7*30) -> 614.28571
B12: OCTUBRE | C12: 587450 | D12: =SUMIFS(FORECAST!G10:G295,FORECAST!B10:B295, ">="&"01/10/2026",FORECAST!B10:B295, "<="&"31/10/2026") -> 84680 | E12: =D12/C12 -> 0.14414844 | F12: =COUNTIF('PLANNING 2026'!C117:AG123,"Garantizado")/COUNTA('PLANNING 2026'!C117:AG123) -> 0.19354839 | G12: =D12/(7*31) -> 390.23041
B13: NOVIEMBRE | C13: 568500 | D13: =SUMIFS(FORECAST!G11:G194,FORECAST!B11:B194, ">="&"01/11/2026",FORECAST!B11:B194, "<="&"30/11/2026") -> 0 | E13: =D13/C13 -> 0 | F13: =COUNTIF('PLANNING 2026'!C129:AF135,"Garantizado")/COUNTA('PLANNING 2026'!C129:AF135) -> 0.15714286 | G13: =D13/(7*30) -> 0
B14: DICIEMBRE | C14: 587450 | D14: =SUMIFS(FORECAST!G12:G146,FORECAST!B12:B146, ">="&"01/12/2026",FORECAST!B12:B146, "<="&"30/12/2026") -> 0 | E14: =D14/C14 -> 0 | F14: =COUNTIF('PLANNING 2026'!C141:AF147,"Garantizado")/COUNTA('PLANNING 2026'!C141:AF147) -> 0.0095238095 | G14: =D14/(7*30) -> 0
B15: TOTAL | C15: =SUM(C4:C13) -> 5741850 | D15: =SUM(D4:D14) -> 523706 | E15: =D15/C15 -> 0.091208583 | F15: =AVERAGE(F3:F14) -> 0.18512336 | G15: =D15/(7*365) -> 204.97299

Sheet % de Ocupación x Salón Anual
D3: DIAS OCUPADO | E3: %
C4: LUGONES | D4: =COUNTIF('PLANNING 2026'!C24:AD24, "Garantizado")+COUNTIF('PLANNING 2026'!C35:AG35, "Garantizado")+COUNTIF('PLANNING 2026'!C47:AF47, "Garantizado")+COUNTIF('PLANNING 2026'!C58:AG58,"Garantizado")+COUNTIF('PLANNING 2026'!C70:AF70,"Garantizado")+COUNTIF('PLANNING 2026'!C82:AG82,"Garantizado")+COUNTIF('PLANNING 2026'!C94:AG94,"Garantizado")+COUNTIF('PLANNING 2026'!C105:AF105,"Garantizado")+COUNTIF('PLANNING 2026'!C117:AG117,"Garantizado")+COUNTIF('PLANNING 2026'!C129:AF129,"Garantizado") -> 101 | E4: =D4/365 -> 0.27671233
C5: CHAMPAQUI | D5: =COUNTIF('PLANNING 2026'!C25:AD25, "Garantizado")+COUNTIF('PLANNING 2026'!C36:AG36, "Garantizado")+COUNTIF('PLANNING 2026'!C48:AF48, "Garantizado")+COUNTIF('PLANNING 2026'!C59:AG59,"Garantizado")+COUNTIF('PLANNING 2026'!C71:AF71,"Garantizado")+COUNTIF('PLANNING 2026'!C83:AG83,"Garantizado")+COUNTIF('PLANNING 2026'!C95:AG95,"Garantizado")+COUNTIF('PLANNING 2026'!C106:AF106,"Garantizado")+COUNTIF('PLANNING 2026'!C118:AG118,"Garantizado")+COUNTIF('PLANNING 2026'!C130:AF130,"Garantizado") -> 84 | E5: =D5/365 -> 0.23013699
